Workbook

Sheet Prices
A1: Name | B1: Price | C1: Median Price | D1: Reduced | E1: Kraken Price | F1: Game | G1: Category | H1: Set | I1: PriceCharting Price | J1: TCGplayer Market | K1: TCGplayer Median | L1: TCGplayer Lowest | M1: Sources | N1: PriceCharting Link | O1: TCGplayer Link
A2: 500 Years in the Future - Booster Box | B2: =IF(I2<>"",I2,IF(J2<>"",J2,IF(K2<>"",K2,L2))) -> 267.48 | C2: =MEDIAN(I2:L2) -> 267.48 | D2: =ROUND(C2*(1-Settings!$B$2),2) -> 187.24 | E2: =ROUND(C2*(1-Settings!$B$3),2) -> 187.24 | F2: One Piece | G2: Box | H2: 500 Years in the Future | I2: 267.48 | J2: 326.57 | L2: 81 | M2: PriceCharting + TCGplayer | N2: https://www.pricecharting.com/game/one-piece-500-years-in-the-future/booster-box | O2: https://www.tcgplayer.com/product/532106
A3: 500 Years In The Future Double Pack DP-04 Display Box | B3: =IF(I3<>"",I3,IF(J3<>"",J3,IF(K3<>"",K3,L3))) -> 335.91 | C3: =MEDIAN(I3:L3) -> 335.91 | D3: =ROUND(C3*(1-Settings!$B$2),2) -> 235.14 | E3: =ROUND(C3*(1-Settings!$B$3),2) -> 235.14 | F3: One Piece | G3: Box | H3: 500 Years In The Future | I3: 335.91 | M3: PriceCharting | N3: https://www.pricecharting.com/game/one-piece-500-years-in-the-future/double-pack-dp-04-display-box
A4: A Fist of Divine Speed Booster Box | B4: =IF(I4<>"",I4,IF(J4<>"",J4,IF(K4<>"",K4,L4))) -> 566.03 | C4: =MEDIAN(I4:L4) -> 332.985 | D4: =ROUND(C4*(1-Settings!$B$2),2) -> 233.09 | E4: =ROUND(C4*(1-Settings!$B$3),2) -> 233.09 | F4: One Piece | G4: Box | H4: A Fist of Divine Speed | J4: 566.03 | L4: 99.94 | M4: TCGplayer | O4: https://www.tcgplayer.com/product/620180
A5: Adventure on Kami's Island Booster Box | B5: =IF(I5<>"",I5,IF(J5<>"",J5,IF(K5<>"",K5,L5))) -> 257.25 | C5: =MEDIAN(I5:L5) -> 161.12 | D5: =ROUND(C5*(1-Settings!$B$2),2) -> 112.78 | E5: =ROUND(C5*(1-Settings!$B$3),2) -> 112.78 | F5: One Piece | G5: Box | H5: Adventure on Kami's Island | J5: 257.25 | L5: 64.99 | M5: TCGplayer | O5: https://www.tcgplayer.com/product/682057
A6: Awakening of the New Era - Booster Box | B6: =IF(I6<>"",I6,IF(J6<>"",J6,IF(K6<>"",K6,L6))) -> 1009.57 | C6: =MEDIAN(I6:L6) -> 1009.57 | D6: =ROUND(C6*(1-Settings!$B$2),2) -> 706.7 | E6: =ROUND(C6*(1-Settings!$B$3),2) -> 706.7 | F6: One Piece | G6: Box | H6: Awakening of the New Era | I6: 1009.57 | J6: 1047.1 | L6: 349.95 | M6: PriceCharting + TCGplayer | N6: https://www.pricecharting.com/game/one-piece-awakening-of-the-new-era/booster-box | O6: https://www.tcgplayer.com/product/498734
A7: Awakening Of The New Era Double Pack DP-02 Display Box | B7: =IF(I7<>"",I7,IF(J7<>"",J7,IF(K7<>"",K7,L7))) -> 314.99 | C7: =MEDIAN(I7:L7) -> 314.99 | D7: =ROUND(C7*(1-Settings!$B$2),2) -> 220.49 | E7: =ROUND(C7*(1-Settings!$B$3),2) -> 220.49 | F7: One Piece | G7: Box | H7: Awakening Of The New Era | I7: 314.99 | M7: PriceCharting | N7: https://www.pricecharting.com/game/one-piece-awakening-of-the-new-era/double-pack-dp-02-display-box
A8: Carrying On His Will Booster Box | B8: =IF(I8<>"",I8,IF(J8<>"",J8,IF(K8<>"",K8,L8))) -> 449.11 | C8: =MEDIAN(I8:L8) -> 444.99 | D8: =ROUND(C8*(1-Settings!$B$2),2) -> 311.49 | E8: =ROUND(C8*(1-Settings!$B$3),2) -> 311.49 | F8: One Piece | G8: Box | H8: Carrying On His Will | I8: 449.11 | J8: 444.99 | L8: 24.99 | M8: PriceCharting + TCGplayer | N8: https://www.pricecharting.com/game/one-piece-carrying-on-his-will/booster-box | O8: https://www.tcgplayer.com/product/628352
A9: Emperors in the New World - Booster Box | B9: =IF(I9<>"",I9,IF(J9<>"",J9,IF(K9<>"",K9,L9))) -> 638 | C9: =MEDIAN(I9:L9) -> 638 | D9: =ROUND(C9*(1-Settings!$B$2),2) -> 446.6 | E9: =ROUND(C9*(1-Settings!$B$3),2) -> 446.6 | F9: One Piece | G9: Box | H9: Emperors in the New World | I9: 638 | J9: 641.67 | L9: 180 | M9: PriceCharting + TCGplayer | N9: https://www.pricecharting.com/game/one-piece-emperors-in-the-new-world/booster-box | O9: https://www.tcgplayer.com/product/563834
A10: Emperors In The New World Double Pack DP-06 Display Box | B10: =IF(I10<>"",I10,IF(J10<>"",J10,IF(K10<>"",K10,L10))) -> 311 | C10: =MEDIAN(I10:L10) -> 311 | D10: =ROUND(C10*(1-Settings!$B$2),2) -> 217.7 | E10: =ROUND(C10*(1-Settings!$B$3),2) -> 217.7 | F10: One Piece | G10: Box | H10: Emperors In The New World | I10: 311 | M10: PriceCharting | N10: https://www.pricecharting.com/game/one-piece-emperors-in-the-new-world/double-pack-dp-06-display-box
A11: Extra Booster Anime 25th Collection Booster Box | B11: =IF(I11<>"",I11,IF(J11<>"",J11,IF(K11<>"",K11,L11))) -> 779.99 | C11: =MEDIAN(I11:L11) -> 779.99 | D11: =ROUND(C11*(1-Settings!$B$2),2) -> 545.99 | E11: =ROUND(C11*(1-Settings!$B$3),2) -> 545.99 | F11: One Piece | G11: Box | H11: Extra Booster Anime 25th Collection | I11: 779.99 | M11: PriceCharting | N11: https://www.pricecharting.com/game/one-piece-extra-booster-anime-25th-collection/booster-box
A12: Extra Booster Heroines Edition Booster Box | B12: =IF(I12<>"",I12,IF(J12<>"",J12,IF(K12<>"",K12,L12))) -> 323.97 | C12: =MEDIAN(I12:L12) -> 323.97 | D12: =ROUND(C12*(1-Settings!$B$2),2) -> 226.78 | E12: =ROUND(C12*(1-Settings!$B$3),2) -> 226.78 | F12: One Piece | G12: Box | H12: Extra Booster Heroines Edition | I12: 323.97 | M12: PriceCharting | N12: https://www.pricecharting.com/game/one-piece-extra-booster-heroines-edition/booster-box
A13: Extra Booster Memorial Collection Sealed Booster Box | B13: =IF(I13<>"",I13,IF(J13<>"",J13,IF(K13<>"",K13,L13))) -> 870.13 | C13: =MEDIAN(I13:L13) -> 870.13 | D13: =ROUND(C13*(1-Settings!$B$2),2) -> 609.09 | E13: =ROUND(C13*(1-Settings!$B$3),2) -> 609.09 | F13: One Piece | G13: Box | H13: Extra Booster Memorial Collection | I13: 870.13 | M13: PriceCharting | N13: https://www.pricecharting.com/game/one-piece-extra-booster-memorial-collection/sealed-booster-box
A14: Memorial Collection - Booster Box | B14: =IF(I14<>"",I14,IF(J14<>"",J14,IF(K14<>"",K14,L14))) -> 875.09 | C14: =MEDIAN(I14:L14) -> 862.545 | D14: =ROUND(C14*(1-Settings!$B$2),2) -> 603.78 | E14: =ROUND(C14*(1-Settings!$B$3),2) -> 603.78 | F14: One Piece | G14: Box | H14: Extra Booster: Memorial Collection | J14: 875.09 | L14: 850 | M14: TCGplayer | O14: https://www.tcgplayer.com/product/521161
A15: Extra Booster: One Piece Heroines Edition Vol.2 - Booster Box | B15: =IF(I15<>"",I15,IF(J15<>"",J15,IF(K15<>"",K15,L15))) -> 357.4 | C15: =MEDIAN(I15:L15) -> 352.535 | D15: =ROUND(C15*(1-Settings!$B$2),2) -> 246.77 | E15: =ROUND(C15*(1-Settings!$B$3),2) -> 246.77 | F15: One Piece | G15: Box | H15: Extra Booster: One Piece Heroines Edition Vol. 2 | J15: 357.4 | L15: 347.67 | M15: TCGplayer | O15: https://www.tcgplayer.com/product/711385
A16: Fist Of Divine Speed Booster Box | B16: =IF(I16<>"",I16,IF(J16<>"",J16,IF(K16<>"",K16,L16))) -> 588.37 | C16: =MEDIAN(I16:L16) -> 588.37 | D16: =ROUND(C16*(1-Settings!$B$2),2) -> 411.86 | E16: =ROUND(C16*(1-Settings!$B$3),2) -> 411.86 | F16: One Piece | G16: Box | H16: Fist Of Divine Speed | I16: 588.37 | M16: PriceCharting | N16: https://www.pricecharting.com/game/one-piece-fist-of-divine-speed/booster-box
A17: Japanese 500 Years In The Future Booster Box | B17: =IF(I17<>"",I17,IF(J17<>"",J17,IF(K17<>"",K17,L17))) -> 82.77 | C17: =MEDIAN(I17:L17) -> 82.77 | D17: =ROUND(C17*(1-Settings!$B$2),2) -> 57.94 | E17: =ROUND(C17*(1-Settings!$B$3),2) -> 57.94 | F17: One Piece | G17: Box | H17: Japanese 500 Years In The Future | I17: 82.77 | M17: PriceCharting | N17: https://www.pricecharting.com/game/one-piece-japanese-500-years-in-the-future/booster-box
A18: Japanese Awakening Of The New Era Booster Box | B18: =IF(I18<>"",I18,IF(J18<>"",J18,IF(K18<>"",K18,L18))) -> 208.46 | C18: =MEDIAN(I18:L18) -> 208.46 | D18: =ROUND(C18*(1-Settings!$B$2),2) -> 145.92 | E18: =ROUND(C18*(1-Settings!$B$3),2) -> 145.92 | F18: One Piece | G18: Box | H18: Japanese Awakening Of The New Era | I18: 208.46 | M18: PriceCharting | N18: https://www.pricecharting.com/game/one-piece-japanese-awakening-of-the-new-era/booster-box
A19: Japanese Carrying On His Will Booster Box | B19: =IF(I19<>"",I19,IF(J19<>"",J19,IF(K19<>"",K19,L19))) -> 130.51 | C19: =MEDIAN(I19:L19) -> 130.51 | D19: =ROUND(C19*(1-Settings!$B$2),2) -> 91.36 | E19: =ROUND(C19*(1-Settings!$B$3),2) -> 91.36 | F19: One Piece | G19: Box | H19: Japanese Carrying On His Will | I19: 130.51 | M19: PriceCharting | N19: https://www.pricecharting.com/game/one-piece-japanese-carrying-on-his-will/booster-box
A20: Japanese Emperors In The New World Booster Box | B20: =IF(I20<>"",I20,IF(J20<>"",J20,IF(K20<>"",K20,L20))) -> 115.63 | C20: =MEDIAN(I20:L20) -> 115.63 | D20: =ROUND(C20*(1-Settings!$B$2),2) -> 80.94 | E20: =ROUND(C20*(1-Settings!$B$3),2) -> 80.94 | F20: One Piece | G20: Box | H20: Japanese Emperors In The New World | I20: 115.63 | M20: PriceCharting | N20: https://www.pricecharting.com/game/one-piece-japanese-emperors-in-the-new-world/booster-box
A21: Japanese Extra Booster Anime 25th Collection Booster Box | B21: =IF(I21<>"",I21,IF(J21<>"",J21,IF(K21<>"",K21,L21))) -> 134.5 | C21: =MEDIAN(I21:L21) -> 134.5 | D21: =ROUND(C21*(1-Settings!$B$2),2) -> 94.15 | E21: =ROUND(C21*(1-Settings!$B$3),2) -> 94.15 | F21: One Piece | G21: Box | H21: Japanese Extra Booster Anime 25th Collection | I21: 134.5 | M21: PriceCharting | N21: https://www.pricecharting.com/game/one-piece-japanese-extra-booster-anime-25th-collection/booster-box
A22: Japanese Extra Booster Egghead Crisis Booster Box | B22: =IF(I22<>"",I22,IF(J22<>"",J22,IF(K22<>"",K22,L22))) -> 91.19 | C22: =MEDIAN(I22:L22) -> 91.19 | D22: =ROUND(C22*(1-Settings!$B$2),2) -> 63.83 | E22: =ROUND(C22*(1-Settings!$B$3),2) -> 63.83 | F22: One Piece | G22: Box | H22: Japanese Extra Booster Egghead Crisis | I22: 91.19 | M22: PriceCharting | N22: https://www.pricecharting.com/game/one-piece-japanese-extra-booster-egghead-crisis/booster-box
A23: Japanese Extra Booster Heroines Edition Booster Box | B23: =IF(I23<>"",I23,IF(J23<>"",J23,IF(K23<>"",K23,L23))) -> 115 | C23: =MEDIAN(I23:L23) -> 115 | D23: =ROUND(C23*(1-Settings!$B$2),2) -> 80.5 | E23: =ROUND(C23*(1-Settings!$B$3),2) -> 80.5 | F23: One Piece | G23: Box | H23: Japanese Extra Booster Heroines Edition | I23: 115 | M23: PriceCharting | N23: https://www.pricecharting.com/game/one-piece-japanese-extra-booster-heroines-edition/booster-box
A24: Japanese Extra Booster Memorial Collection Booster Box | B24: =IF(I24<>"",I24,IF(J24<>"",J24,IF(K24<>"",K24,L24))) -> 112 | C24: =MEDIAN(I24:L24) -> 112 | D24: =ROUND(C24*(1-Settings!$B$2),2) -> 78.4 | E24: =ROUND(C24*(1-Settings!$B$3),2) -> 78.4 | F24: One Piece | G24: Box | H24: Japanese Extra Booster Memorial Collection | I24: 112 | M24: PriceCharting | N24: https://www.pricecharting.com/game/one-piece-japanese-extra-booster-memorial-collection/booster-box
A25: Japanese Fist Of Divine Speed Booster Box | B25: =IF(I25<>"",I25,IF(J25<>"",J25,IF(K25<>"",K25,L25))) -> 132.99 | C25: =MEDIAN(I25:L25) -> 132.99 | D25: =ROUND(C25*(1-Settings!$B$2),2) -> 93.09 | E25: =ROUND(C25*(1-Settings!$B$3),2) -> 93.09 | F25: One Piece | G25: Box | H25: Japanese Fist Of Divine Speed | I25: 132.99 | M25: PriceCharting | N25: https://www.pricecharting.com/game/one-piece-japanese-fist-of-divine-speed/booster-box
A26: Japanese Kingdoms Of Intrigue Booster Box | B26: =IF(I26<>"",I26,IF(J26<>"",J26,IF(K26<>"",K26,L26))) -> 131.28 | C26: =MEDIAN(I26:L26) -> 131.28 | D26: =ROUND(C26*(1-Settings!$B$2),2) -> 91.9 | E26: =ROUND(C26*(1-Settings!$B$3),2) -> 91.9 | F26: One Piece | G26: Box | H26: Japanese Kingdoms Of Intrigue | I26: 131.28 | M26: PriceCharting | N26: https://www.pricecharting.com/game/one-piece-japanese-kingdoms-of-intrigue/booster-box
A27: Japanese Legacy Of The Master Booster Box | B27: =IF(I27<>"",I27,IF(J27<>"",J27,IF(K27<>"",K27,L27))) -> 78.97 | C27: =MEDIAN(I27:L27) -> 78.97 | D27: =ROUND(C27*(1-Settings!$B$2),2) -> 55.28 | E27: =ROUND(C27*(1-Settings!$B$3),2) -> 55.28 | F27: One Piece | G27: Box | H27: Japanese Legacy Of The Master | I27: 78.97 | M27: PriceCharting | N27: https://www.pricecharting.com/game/one-piece-japanese-legacy-of-the-master/booster-box
... A36: Japanese Wings Of The Captain Booster Box | B36: =IF(I36<>"",I36,IF(J36<>"",J36,IF(K36<>"",K36,L36))) -> 184.9 | C36: =MEDIAN(I36:L36) -> 184.9 | D36: =ROUND(C36*(1-Settings!$B$2),2) -> 129.43 | E36: =ROUND(C36*(1-Settings!$B$3),2) -> 129.43 | F36: One Piece | G36: Box | H36: Japanese Wings Of The Captain | I36: 184.9 | M36: PriceCharting | N36: https://www.pricecharting.com/game/one-piece-japanese-wings-of-the-captain/booster-box
A37: Kingdoms of Intrigue - Booster Box | B37: =IF(I37<>"",I37,IF(J37<>"",J37,IF(K37<>"",K37,L37))) -> 484.6 | C37: =MEDIAN(I37:L37) -> 484.6 | D37: =ROUND(C37*(1-Settings!$B$2),2) -> 339.22 | E37: =ROUND(C37*(1-Settings!$B$3),2) -> 339.22 | F37: One Piece | G37: Box | H37: Kingdoms of Intrigue | I37: 484.6 | J37: 500.19 | L37: 479.98 | M37: PriceCharting + TCGplayer | N37: https://www.pricecharting.com/game/one-piece-kingdoms-of-intrigue/booster-box | O37: https://www.tcgplayer.com/product/485833
A38: Kingdoms Of Intrigue Double Pack DP-01 Display Box | B38: =IF(I38<>"",I38,IF(J38<>"",J38,IF(K38<>"",K38,L38))) -> 212.54 | C38: =MEDIAN(I38:L38) -> 212.54 | D38: =ROUND(C38*(1-Settings!$B$2),2) -> 148.78 | E38: =ROUND(C38*(1-Settings!$B$3),2) -> 148.78 | F38: One Piece | G38: Box | H38: Kingdoms Of Intrigue | I38: 212.54 | M38: PriceCharting | N38: https://www.pricecharting.com/game/one-piece-kingdoms-of-intrigue/double-pack-dp-01-display-box
A39: Legacy of the Master Booster Box | B39: =IF(I39<>"",I39,IF(J39<>"",J39,IF(K39<>"",K39,L39))) -> 290 | C39: =MEDIAN(I39:L39) -> 290 | D39: =ROUND(C39*(1-Settings!$B$2),2) -> 203 | E39: =ROUND(C39*(1-Settings!$B$3),2) -> 203 | F39: One Piece | G39: Box | H39: Legacy of the Master | I39: 290 | J39: 290.66 | L39: 22.98 | M39: PriceCharting + TCGplayer | N39: https://www.pricecharting.com/game/one-piece-legacy-of-the-master/booster-box | O39: https://www.tcgplayer.com/product/628346
A40: Legacy Of The Master Double Pack DP-08 Display Box | B40: =IF(I40<>"",I40,IF(J40<>"",J40,IF(K40<>"",K40,L40))) -> 328.31 | C40: =MEDIAN(I40:L40) -> 328.31 | D40: =ROUND(C40*(1-Settings!$B$2),2) -> 229.82 | E40: =ROUND(C40*(1-Settings!$B$3),2) -> 229.82 | F40: One Piece | G40: Box | H40: Legacy Of The Master | I40: 328.31 | M40: PriceCharting | N40: https://www.pricecharting.com/game/one-piece-legacy-of-the-master/double-pack-dp-08-display-box
A41: Paramount War - Booster Box | B41: =IF(I41<>"",I41,IF(J41<>"",J41,IF(K41<>"",K41,L41))) -> 520.26 | C41: =MEDIAN(I41:L41) -> 520.26 | D41: =ROUND(C41*(1-Settings!$B$2),2) -> 364.18 | E41: =ROUND(C41*(1-Settings!$B$3),2) -> 364.18 | F41: One Piece | G41: Box | H41: Paramount War | I41: 520.26 | J41: 553.65 | L41: 69.99 | M41: PriceCharting + TCGplayer | N41: https://www.pricecharting.com/game/one-piece-paramount-war/booster-box | O41: https://www.tcgplayer.com/product/455866
A42: Pillars of Strength - Booster Box | B42: =IF(I42<>"",I42,IF(J42<>"",J42,IF(K42<>"",K42,L42))) -> 509.74 | C42: =MEDIAN(I42:L42) -> 506.49 | D42: =ROUND(C42*(1-Settings!$B$2),2) -> 354.54 | E42: =ROUND(C42*(1-Settings!$B$3),2) -> 354.54 | F42: One Piece | G42: Box | H42: Pillars of Strength | I42: 509.74 | J42: 506.49 | L42: 69.99 | M42: PriceCharting + TCGplayer | N42: https://www.pricecharting.com/game/one-piece-pillars-of-strength/booster-box | O42: https://www.tcgplayer.com/product/477176
A43: Premium Booster - Booster Box | B43: =IF(I43<>"",I43,IF(J43<>"",J43,IF(K43<>"",K43,L43))) -> 903.88 | C43: =MEDIAN(I43:L43) -> 546.935 | D43: =ROUND(C43*(1-Settings!$B$2),2) -> 382.85 | E43: =ROUND(C43*(1-Settings!$B$3),2) -> 382.85 | F43: One Piece | G43: Box | H43: Premium Booster -The Best- | J43: 903.88 | L43: 189.99 | M43: TCGplayer | O43: https://www.tcgplayer.com/product/545399
A44: Premium Booster Vol. 2 - Booster Box | B44: =IF(I44<>"",I44,IF(J44<>"",J44,IF(K44<>"",K44,L44))) -> 377.53 | C44: =MEDIAN(I44:L44) -> 238.24 | D44: =ROUND(C44*(1-Settings!$B$2),2) -> 166.77 | E44: =ROUND(C44*(1-Settings!$B$3),2) -> 166.77 | F44: One Piece | G44: Box | H44: Premium Booster -The Best- Vol. 2 | J44: 377.53 | L44: 98.95 | M44: TCGplayer | O44: https://www.tcgplayer.com/product/628452
A45: Premium Booster 2 Booster Box | B45: =IF(I45<>"",I45,IF(J45<>"",J45,IF(K45<>"",K45,L45))) -> 379.48 | C45: =MEDIAN(I45:L45) -> 379.48 | D45: =ROUND(C45*(1-Settings!$B$2),2) -> 265.64 | E45: =ROUND(C45*(1-Settings!$B$3),2) -> 265.64 | F45: One Piece | G45: Box | H45: Premium Booster 2 | I45: 379.48 | M45: PriceCharting | N45: https://www.pricecharting.com/game/one-piece-premium-booster-2/booster-box
A46: Romance Dawn - Booster Box (Wave 1 - Blue) | B46: =IF(I46<>"",I46,IF(J46<>"",J46,IF(K46<>"",K46,L46))) -> 4636.13 | C46: =MEDIAN(I46:L46) -> 2418.065 | D46: =ROUND(C46*(1-Settings!$B$2),2) -> 1692.65 | E46: =ROUND(C46*(1-Settings!$B$3),2) -> 1692.65 | F46: One Piece | G46: Box | H46: Romance Dawn | J46: 4636.13 | L46: 200 | M46: TCGplayer | O46: https://www.tcgplayer.com/product/450086
A47: Romance Dawn - Booster Box (Wave 2 - White) | B47: =IF(I47<>"",I47,IF(J47<>"",J47,IF(K47<>"",K47,L47))) -> 1394.51 | C47: =MEDIAN(I47:L47) -> 704.75 | D47: =ROUND(C47*(1-Settings!$B$2),2) -> 493.33 | E47: =ROUND(C47*(1-Settings!$B$3),2) -> 493.33 | F47: One Piece | G47: Box | H47: Romance Dawn | J47: 1394.51 | L47: 14.99 | M47: TCGplayer | O47: https://www.tcgplayer.com/product/557280
A48: Romance Dawn Booster Box | B48: =IF(I48<>"",I48,IF(J48<>"",J48,IF(K48<>"",K48,L48))) -> 1191.82 | C48: =MEDIAN(I48:L48) -> 1191.82 | D48: =ROUND(C48*(1-Settings!$B$2),2) -> 834.27 | E48: =ROUND(C48*(1-Settings!$B$3),2) -> 834.27 | F48: One Piece | G48: Box | H48: Romance Dawn | I48: 1191.82 | M48: PriceCharting | N48: https://www.pricecharting.com/game/one-piece-romance-dawn/booster-box
...

Sheet Other Sealed
A1: Name | B1: Price | C1: Median Price | D1: Reduced | E1: Kraken Price | F1: Game | G1: Category | H1: Set | I1: PriceCharting Price | J1: TCGplayer Market | K1: TCGplayer Median | L1: TCGplayer Lowest | M1: Sources | N1: PriceCharting Link | O1: TCGplayer Link
A2: Japanese Premium Booster Sealed Storage Box Set | B2: =IF(I2<>"",I2,IF(J2<>"",J2,IF(K2<>"",K2,L2))) -> 352.9 | C2: =MEDIAN(I2:L2) -> 352.9 | D2: =ROUND(C2*(1-Settings!$B$2),2) -> 247.03 | E2: =ROUND(C2*(1-Settings!$B$3),2) -> 247.03 | F2: One Piece | G2: Accessory | H2: Japanese Premium Booster | I2: 352.9 | M2: PriceCharting | N2: https://www.pricecharting.com/game/one-piece-japanese-premium-booster/sealed-storage-box-set
A3: Official 9 Pocket Binder Vol.1 (Sealed Promotional Bundle) | B3: =IF(I3<>"",I3,IF(J3<>"",J3,IF(K3<>"",K3,L3))) -> 71.67 | C3: =MEDIAN(I3:L3) -> 50.835 | D3: =ROUND(C3*(1-Settings!$B$2),2) -> 35.58 | E3: =ROUND(C3*(1-Settings!$B$3),2) -> 35.58 | F3: One Piece | G3: Accessory | H3: One Piece Promotion Cards | J3: 71.67 | L3: 30 | M3: TCGplayer | O3: https://www.tcgplayer.com/product/717458
A4: Seven Warlords of the Sea Binder Set (Bundle) | B4: =IF(I4<>"",I4,IF(J4<>"",J4,IF(K4<>"",K4,L4))) -> 351.83 | C4: =MEDIAN(I4:L4) -> 348.41 | D4: =ROUND(C4*(1-Settings!$B$2),2) -> 243.89 | E4: =ROUND(C4*(1-Settings!$B$3),2) -> 243.89 | F4: One Piece | G4: Accessory | H4: One Piece Promotion Cards | J4: 351.83 | L4: 344.99 | M4: TCGplayer | O4: https://www.tcgplayer.com/product/700808
A5: Promo Sealed Anniversary Storage Box | B5: =IF(I5<>"",I5,IF(J5<>"",J5,IF(K5<>"",K5,L5))) -> 109.32 | C5: =MEDIAN(I5:L5) -> 109.32 | D5: =ROUND(C5*(1-Settings!$B$2),2) -> 76.52 | E5: =ROUND(C5*(1-Settings!$B$3),2) -> 76.52 | F5: One Piece | G5: Accessory | H5: Promo | I5: 109.32 | M5: PriceCharting | N5: https://www.pricecharting.com/game/one-piece-promo/sealed-anniversary-storage-box
A6: Seven Warlords Of The Sea Binder Set Sealed Binder Set | B6: =IF(I6<>"",I6,IF(J6<>"",J6,IF(K6<>"",K6,L6))) -> 198.96 | C6: =MEDIAN(I6:L6) -> 198.96 | D6: =ROUND(C6*(1-Settings!$B$2),2) -> 139.27 | E6: =ROUND(C6*(1-Settings!$B$3),2) -> 139.27 | F6: One Piece | G6: Accessory | H6: Seven Warlords Of The Sea Binder Set | I6: 198.96 | M6: PriceCharting | N6: https://www.pricecharting.com/game/one-piece-seven-warlords-of-the-sea-binder-set/sealed-binder-set
A7: 500 Years in the Future - Booster Box Case | B7: =IF(I7<>"",I7,IF(J7<>"",J7,IF(K7<>"",K7,L7))) -> 3526 | C7: =MEDIAN(I7:L7) -> 3680.5 | D7: =ROUND(C7*(1-Settings!$B$2),2) -> 2576.35 | E7: =ROUND(C7*(1-Settings!$B$3),2) -> 2576.35 | F7: One Piece | G7: Case/Display | H7: 500 Years in the Future | J7: 3526 | L7: 3835 | M7: TCGplayer | O7: https://www.tcgplayer.com/product/532107
A8: Double Pack Set Volume 4 Display | B8: =IF(I8<>"",I8,IF(J8<>"",J8,IF(K8<>"",K8,L8))) -> 376.06 | C8: =MEDIAN(I8:L8) -> 443.03 | D8: =ROUND(C8*(1-Settings!$B$2),2) -> 310.12 | E8: =ROUND(C8*(1-Settings!$B$3),2) -> 310.12 | F8: One Piece | G8: Case/Display | H8: 500 Years in the Future | J8: 376.06 | L8: 510 | M8: TCGplayer | O8: https://www.tcgplayer.com/product/549495
A9: A Fist of Divine Speed Booster Box Case | B9: =IF(I9<>"",I9,IF(J9<>"",J9,IF(K9<>"",K9,L9))) -> 6180.79 | C9: =MEDIAN(I9:L9) -> 6503.39 | D9: =ROUND(C9*(1-Settings!$B$2),2) -> 4552.37 | E9: =ROUND(C9*(1-Settings!$B$3),2) -> 4552.37 | F9: One Piece | G9: Case/Display | H9: A Fist of Divine Speed | J9: 6180.79 | L9: 6825.99 | M9: TCGplayer | O9: https://www.tcgplayer.com/product/620181
A10: Double Pack Set Volume 7 Display | B10: =IF(I10<>"",I10,IF(J10<>"",J10,IF(K10<>"",K10,L10))) -> 652.52 | C10: =MEDIAN(I10:L10) -> 739.26 | D10: =ROUND(C10*(1-Settings!$B$2),2) -> 517.48 | E10: =ROUND(C10*(1-Settings!$B$3),2) -> 517.48 | F10: One Piece | G10: Case/Display | H10: A Fist of Divine Speed | J10: 652.52 | L10: 826 | M10: TCGplayer | O10: https://www.tcgplayer.com/product/606562
A11: Adventure on Kami's Island Booster Box Case | B11: =IF(I11<>"",I11,IF(J11<>"",J11,IF(K11<>"",K11,L11))) -> 2943 | C11: =MEDIAN(I11:L11) -> 2929 | D11: =ROUND(C11*(1-Settings!$B$2),2) -> 2050.3 | E11: =ROUND(C11*(1-Settings!$B$3),2) -> 2050.3 | F11: One Piece | G11: Case/Display | H11: Adventure on Kami's Island | J11: 2943 | L11: 2915 | M11: TCGplayer | O11: https://www.tcgplayer.com/product/682058
A12: Double Pack Set Vol. 10 Display | B12: =IF(I12<>"",I12,IF(J12<>"",J12,IF(K12<>"",K12,L12))) -> 254.76 | C12: =MEDIAN(I12:L12) -> 287.13 | D12: =ROUND(C12*(1-Settings!$B$2),2) -> 200.99 | E12: =ROUND(C12*(1-Settings!$B$3),2) -> 200.99 | F12: One Piece | G12: Case/Display | H12: Adventure on Kami's Island | J12: 254.76 | L12: 319.5 | M12: TCGplayer | O12: https://www.tcgplayer.com/product/682790
A13: Awakening of the New Era - Booster Box Case | B13: =IF(I13<>"",I13,IF(J13<>"",J13,IF(K13<>"",K13,L13))) -> 12573.53 | C13: =MEDIAN(I13:L13) -> 8786.76 | D13: =ROUND(C13*(1-Settings!$B$2),2) -> 6150.73 | E13: =ROUND(C13*(1-Settings!$B$3),2) -> 6150.73 | F13: One Piece | G13: Case/Display | H13: Awakening of the New Era | J13: 12573.53 | L13: 4999.99 | M13: TCGplayer | O13: https://www.tcgplayer.com/product/498735
A14: Double Pack Set Volume 2 Display | B14: =IF(I14<>"",I14,IF(J14<>"",J14,IF(K14<>"",K14,L14))) -> 1512.59 | C14: =MEDIAN(I14:L14) -> 1606.295 | D14: =ROUND(C14*(1-Settings!$B$2),2) -> 1124.41 | E14: =ROUND(C14*(1-Settings!$B$3),2) -> 1124.41 | F14: One Piece | G14: Case/Display | H14: Awakening of the New Era | J14: 1512.59 | L14: 1700 | M14: TCGplayer | O14: https://www.tcgplayer.com/product/527062
A15: Double Pack Set Volume 2 Display Case | B15: =IF(I15<>"",I15,IF(J15<>"",J15,IF(K15<>"",K15,L15))) -> 15000 | C15: =MEDIAN(I15:L15) -> 15000 | D15: =ROUND(C15*(1-Settings!$B$2),2) -> 10500 | E15: =ROUND(C15*(1-Settings!$B$3),2) -> 10500 | F15: One Piece | G15: Case/Display | H15: Awakening of the New Era | L15: 15000 | M15: TCGplayer | O15: https://www.tcgplayer.com/product/527063
A16: Carrying On His Will Booster Box Case | B16: =IF(I16<>"",I16,IF(J16<>"",J16,IF(K16<>"",K16,L16))) -> 6000.87 | C16: =MEDIAN(I16:L16) -> 4100.43 | D16: =ROUND(C16*(1-Settings!$B$2),2) -> 2870.3 | E16: =ROUND(C16*(1-Settings!$B$3),2) -> 2870.3 | F16: One Piece | G16: Case/Display | H16: Carrying On His Will | J16: 6000.87 | L16: 2199.99 | M16: TCGplayer | O16: https://www.tcgplayer.com/product/628353
A17: Double Pack Set Volume 6 Display | B17: =IF(I17<>"",I17,IF(J17<>"",J17,IF(K17<>"",K17,L17))) -> 775.49 | C17: =MEDIAN(I17:L17) -> 787.24 | D17: =ROUND(C17*(1-Settings!$B$2),2) -> 551.07 | E17: =ROUND(C17*(1-Settings!$B$3),2) -> 551.07 | F17: One Piece | G17: Case/Display | H17: Emperors in the New World | J17: 775.49 | L17: 798.99 | M17: TCGplayer | O17: https://www.tcgplayer.com/product/563843
A18: Emperors in the New World - Booster Box Case | B18: =IF(I18<>"",I18,IF(J18<>"",J18,IF(K18<>"",K18,L18))) -> 7558.56 | C18: =MEDIAN(I18:L18) -> 6279.28 | D18: =ROUND(C18*(1-Settings!$B$2),2) -> 4395.5 | E18: =ROUND(C18*(1-Settings!$B$3),2) -> 4395.5 | F18: One Piece | G18: Case/Display | H18: Emperors in the New World | J18: 7558.56 | L18: 5000 | M18: TCGplayer | O18: https://www.tcgplayer.com/product/563835
A19: Extra Booster: Anime 25th Collection Box Case | B19: =IF(I19<>"",I19,IF(J19<>"",J19,IF(K19<>"",K19,L19))) -> 7905.16 | C19: =MEDIAN(I19:L19) -> 7803.075 | D19: =ROUND(C19*(1-Settings!$B$2),2) -> 5462.15 | E19: =ROUND(C19*(1-Settings!$B$3),2) -> 5462.15 | F19: One Piece | G19: Case/Display | H19: Extra Booster: Anime 25th Collection | J19: 7905.16 | L19: 7700.99 | M19: TCGplayer | O19: https://www.tcgplayer.com/product/594070
A20: Memorial Collection - Booster Box Case | B20: =IF(I20<>"",I20,IF(J20<>"",J20,IF(K20<>"",K20,L20))) -> 10999.99 | C20: =MEDIAN(I20:L20) -> 10999.99 | D20: =ROUND(C20*(1-Settings!$B$2),2) -> 7699.99 | E20: =ROUND(C20*(1-Settings!$B$3),2) -> 7699.99 | F20: One Piece | G20: Case/Display | H20: Extra Booster: Memorial Collection | L20: 10999.99 | M20: TCGplayer | O20: https://www.tcgplayer.com/product/521162
A21: Extra Booster: One Piece Heroines Edition Box Case | B21: =IF(I21<>"",I21,IF(J21<>"",J21,IF(K21<>"",K21,L21))) -> 3581.52 | C21: =MEDIAN(I21:L21) -> 3515.755 | D21: =ROUND(C21*(1-Settings!$B$2),2) -> 2461.03 | E21: =ROUND(C21*(1-Settings!$B$3),2) -> 2461.03 | F21: One Piece | G21: Case/Display | H21: Extra Booster: One Piece Heroines Edition | J21: 3581.52 | L21: 3449.99 | M21: TCGplayer | O21: https://www.tcgplayer.com/product/666892
A22: Extra Booster: One Piece Heroines Edition Vol.2 - Booster Box Case | B22: =IF(I22<>"",I22,IF(J22<>"",J22,IF(K22<>"",K22,L22))) -> 3705.74 | C22: =MEDIAN(I22:L22) -> 3698.245 | D22: =ROUND(C22*(1-Settings!$B$2),2) -> 2588.77 | E22: =ROUND(C22*(1-Settings!$B$3),2) -> 2588.77 | F22: One Piece | G22: Case/Display | H22: Extra Booster: One Piece Heroines Edition Vol. 2 | J22: 3705.74 | L22: 3690.75 | M22: TCGplayer | O22: https://www.tcgplayer.com/product/711386
A23: Double Pack Set Volume 1 Display | B23: =IF(I23<>"",I23,IF(J23<>"",J23,IF(K23<>"",K23,L23))) -> 874.85 | C23: =MEDIAN(I23:L23) -> 839.925 | D23: =ROUND(C23*(1-Settings!$B$2),2) -> 587.95 | E23: =ROUND(C23*(1-Settings!$B$3),2) -> 587.95 | F23: One Piece | G23: Case/Display | H23: Kingdoms of Intrigue | J23: 874.85 | L23: 805 | M23: TCGplayer | O23: https://www.tcgplayer.com/product/514029
A24: Kingdoms of Intrigue - Booster Box Case | B24: =IF(I24<>"",I24,IF(J24<>"",J24,IF(K24<>"",K24,L24))) -> 5990 | C24: =MEDIAN(I24:L24) -> 5990 | D24: =ROUND(C24*(1-Settings!$B$2),2) -> 4193 | E24: =ROUND(C24*(1-Settings!$B$3),2) -> 4193 | F24: One Piece | G24: Case/Display | H24: Kingdoms of Intrigue | L24: 5990 | M24: TCGplayer | O24: https://www.tcgplayer.com/product/485834
A25: Learn Together Deck Set Display | B25: =IF(I25<>"",I25,IF(J25<>"",J25,IF(K25<>"",K25,L25))) -> 266.09 | C25: =MEDIAN(I25:L25) -> 280.54 | D25: =ROUND(C25*(1-Settings!$B$2),2) -> 196.38 | E25: =ROUND(C25*(1-Settings!$B$3),2) -> 196.38 | F25: One Piece | G25: Case/Display | H25: Learn Together Deck Set | J25: 266.09 | L25: 294.99 | M25: TCGplayer | O25: https://www.tcgplayer.com/product/628479
A26: Double Pack Set Vol. 8 Display | B26: =IF(I26<>"",I26,IF(J26<>"",J26,IF(K26<>"",K26,L26))) -> 303.32 | C26: =MEDIAN(I26:L26) -> 324.16 | D26: =ROUND(C26*(1-Settings!$B$2),2) -> 226.91 | E26: =ROUND(C26*(1-Settings!$B$3),2) -> 226.91 | F26: One Piece | G26: Case/Display | H26: Legacy of the Master | J26: 303.32 | L26: 345 | M26: TCGplayer | O26: https://www.tcgplayer.com/product/628349
A27: Legacy of the Master Booster Box Case | B27: =IF(I27<>"",I27,IF(J27<>"",J27,IF(K27<>"",K27,L27))) -> 2814.8 | C27: =MEDIAN(I27:L27) -> 2907.395 | D27: =ROUND(C27*(1-Settings!$B$2),2) -> 2035.18 | E27: =ROUND(C27*(1-Settings!$B$3),2) -> 2035.18 | F27: One Piece | G27: Case/Display | H27: Legacy of the Master | J27: 2814.8 | L27: 2999.99 | M27: TCGplayer | O27: https://www.tcgplayer.com/product/628347
A28: Devil Fruits Collection Vol. 2 Case | B28: =IF(I28<>"",I28,IF(J28<>"",J28,IF(K28<>"",K28,L28))) -> 2500.99 | C28: =MEDIAN(I28:L28) -> 2500.99 | D28: =ROUND(C28*(1-Settings!$B$2),2) -> 1750.69 | E28: =ROUND(C28*(1-Settings!$B$3),2) -> 1750.69 | F28: One Piece | G28: Case/Display | H28: One Piece Collection Sets | L28: 2500.99 | M28: TCGplayer | O28: https://www.tcgplayer.com/product/593447
A29: Gift Collection 2023 Display | B29: =IF(I29<>"",I29,IF(J29<>"",J29,IF(K29<>"",K29,L29))) -> 2246.35 | C29: =MEDIAN(I29:L29) -> 2523.175 | D29: =ROUND(C29*(1-Settings!$B$2),2) -> 1766.22 | E29: =ROUND(C29*(1-Settings!$B$3),2) -> 1766.22 | F29: One Piece | G29: Case/Display | H29: One Piece Promotion Cards | J29: 2246.35 | L29: 2800 | M29: TCGplayer | O29: https://www.tcgplayer.com/product/493744
A30: One Piece Card Game Illustration Box Vol. 5 Case | B30: =IF(I30<>"",I30,IF(J30<>"",J30,IF(K30<>"",K30,L30))) -> 757.85 | C30: =MEDIAN(I30:L30) -> 828.925 | D30: =ROUND(C30*(1-Settings!$B$2),2) -> 580.25 | E30: =ROUND(C30*(1-Settings!$B$3),2) -> 580.25 | F30: One Piece | G30: Case/Display | H30: One Piece Promotion Cards | J30: 757.85 | L30: 900 | M30: TCGplayer | O30: https://www.tcgplayer.com/product/672601
A31: One Piece Card Game Illustration Box Vol. 6 Case | B31: =IF(I31<>"",I31,IF(J31<>"",J31,IF(K31<>"",K31,L31))) -> 682.27 | C31: =MEDIAN(I31:L31) -> 661.13 | D31: =ROUND(C31*(1-Settings!$B$2),2) -> 462.79 | E31: =ROUND(C31*(1-Settings!$B$3),2) -> 462.79 | F31: One Piece | G31: Case/Display | H31: One Piece Promotion Cards | J31: 682.27 | L31: 639.99 | M31: TCGplayer | O31: https://www.tcgplayer.com/product/672604
A32: One Piece Card Game Illustration Box Vol. 7 Case | B32: =IF(I32<>"",I32,IF(J32<>"",J32,IF(K32<>"",K32,L32))) -> 254.74 | C32: =MEDIAN(I32:L32) -> 289.87 | D32: =ROUND(C32*(1-Settings!$B$2),2) -> 202.91 | E32: =ROUND(C32*(1-Settings!$B$3),2) -> 202.91 | F32: One Piece | G32: Case/Display | H32: One Piece Promotion Cards | J32: 254.74 | L32: 325 | M32: TCGplayer | O32: https://www.tcgplayer.com/product/711511
A33: One Piece Card Game Illustration Box Vol. 8 Case | B33: =IF(I33<>"",I33,IF(J33<>"",J33,IF(K33<>"",K33,L33))) -> 259.99 | C33: =MEDIAN(I33:L33) -> 292.495 | D33: =ROUND(C33*(1-Settings!$B$2),2) -> 204.75 | E33: =ROUND(C33*(1-Settings!$B$3),2) -> 204.75 | F33: One Piece | G33: Case/Display | H33: One Piece Promotion Cards | J33: 259.99 | L33: 325 | M33: TCGplayer | O33: https://www.tcgplayer.com/product/711512
A34: One Piece Tin Pack Set Vol. 1 Display | B34: =IF(I34<>"",I34,IF(J34<>"",J34,IF(K34<>"",K34,L34))) -> 480.25 | C34: =MEDIAN(I34:L34) -> 540.12 | D34: =ROUND(C34*(1-Settings!$B$2),2) -> 378.08 | E34: =ROUND(C34*(1-Settings!$B$3),2) -> 378.08 | F34: One Piece | G34: Case/Display | H34: One Piece Promotion Cards | J34: 480.25 | L34: 599.99 | M34: TCGplayer | O34: https://www.tcgplayer.com/product/620280
A35: One Piece Tin Pack Set Vol. 1 Display Case | B35: =IF(I35<>"",I35,IF(J35<>"",J35,IF(K35<>"",K35,L35))) -> 3375.99 | C35: =MEDIAN(I35:L35) -> 3375.99 | D35: =ROUND(C35*(1-Settings!$B$2),2) -> 2363.19 | E35: =ROUND(C35*(1-Settings!$B$3),2) -> 2363.19 | F35: One Piece | G35: Case/Display | H35: One Piece Promotion Cards | L35: 3375.99 | M35: TCGplayer | O35: https://www.tcgplayer.com/product/620281
A36: One Piece Tin Pack Set Vol. 2 Display | B36: =IF(I36<>"",I36,IF(J36<>"",J36,IF(K36<>"",K36,L36))) -> 723.72 | C36: =MEDIAN(I36:L36) -> 753.86 | D36: =ROUND(C36*(1-Settings!$B$2),2) -> 527.7 | E36: =ROUND(C36*(1-Settings!$B$3),2) -> 527.7 | F36: One Piece | G36: Case/Display | H36: One Piece Promotion Cards | J36: 723.72 | L36: 784 | M36: TCGplayer | O36: https://www.tcgplayer.com/product/657218
A37: One Piece Tin Pack Set Vol. 2 Display Case | B37: =IF(I37<>"",I37,IF(J37<>"",J37,IF(K37<>"",K37,L37))) -> 2999.95 | C37: =MEDIAN(I37:L37) -> 3149.975 | D37: =ROUND(C37*(1-Settings!$B$2),2) -> 2204.98 | E37: =ROUND(C37*(1-Settings!$B$3),2) -> 2204.98 | F37: One Piece | G37: Case/Display | H37: One Piece Promotion Cards | J37: 2999.95 | L37: 3300 | M37: TCGplayer | O37: https://www.tcgplayer.com/product/657219
A38: Treasure Booster Set Display Case | B38: =IF(I38<>"",I38,IF(J38<>"",J38,IF(K38<>"",K38,L38))) -> 2473.99 | C38: =MEDIAN(I38:L38) -> 2473.99 | D38: =ROUND(C38*(1-Settings!$B$2),2) -> 1731.79 | E38: =ROUND(C38*(1-Settings!$B$3),2) -> 1731.79 | F38: One Piece | G38: Case/Display | H38: One Piece Promotion Cards | L38: 2473.99 | M38: TCGplayer | O38: https://www.tcgplayer.com/product/646249
A39: Paramount War - Booster Box Case | B39: =IF(I39<>"",I39,IF(J39<>"",J39,IF(K39<>"",K39,L39))) -> 5995 | C39: =MEDIAN(I39:L39) -> 5995 | D39: =ROUND(C39*(1-Settings!$B$2),2) -> 4196.5 | E39: =ROUND(C39*(1-Settings!$B$3),2) -> 4196.5 | F39: One Piece | G39: Case/Display | H39: Paramount War | L39: 5995 | M39: TCGplayer | O39: https://www.tcgplayer.com/product/455867
A40: Pillars of Strength - Booster Box Case | B40: =IF(I40<>"",I40,IF(J40<>"",J40,IF(K40<>"",K40,L40))) -> 6271.2 | C40: =MEDIAN(I40:L40) -> 6271.2 | D40: =ROUND(C40*(1-Settings!$B$2),2) -> 4389.84 | E40: =ROUND(C40*(1-Settings!$B$3),2) -> 4389.84 | F40: One Piece | G40: Case/Display | H40: Pillars of Strength | L40: 6271.2 | M40: TCGplayer | O40: https://www.tcgplayer.com/product/477177
...

Sheet Settings
A1: Settings
A2: Discount (Reduced = Median Price x (1 - Discount)) | B2: 0.3
A3: Kraken discount (Kraken Price = Median Price x (1 - Kraken discount)) | B3: 0.3
A4: Edit the yellow cells only. Every "Reduced" and "Kraken Price" value on the other sheets recalculates from them.
A5: Data collected | B5: 2026-10-14
A6: Sources | B6: PriceCharting (ungraded/sealed sale price, USD) - https://www.pricecharting.com ; TCGplayer (Market, Median, Lowest listing, USD) - https://www.tcgplayer.com
A7: Price | B7: PriceCharting price when available, otherwise TCGplayer Market (then Median, then Lowest).
A8: Median Price | B8: MEDIAN of all price points found for the product (PriceCharting price, TCGplayer Market, Median and Lowest). Products found on both sites are merged into one row.
A9: Categories | B9: Box = booster box / display. Pack = single boosters and blisters. Coffret = elite trainer boxes, collections, tins, bundles, gift sets. Decks, cases and accessories are on the "Other Sealed" sheet.
A10: Scope | B10: Pokemon (English, Japanese, other languages as listed by the sites) and One Piece Card Game sealed products. Products with no price on either site were left out.
A11: Kraken Price | B11: Median Price minus the Kraken discount (Settings!B3, 30% by default): the buy/offer price used by the shop.
